<?xml version="1.0" ?>
<!-- =================================================================================== -->
<!-- |    This document was autogenerated by xacro from src/eddie_description/urdf/eddie_robot.urdf.xacro | -->
<!-- |    EDITING THIS FILE BY HAND IS NOT RECOMMENDED                                 | -->
<!-- =================================================================================== -->
<robot name="eddie_base_with_wheels">
  <!-- Base Footprint -->
  <link name="eddie_base_footprint"/>
  <!-- Additional Component at Center -->
  <link name="eddie_base_link">
    <visual>
      <origin rpy="0 0 0" xyz="0 0 0"/>
      <geometry>
        <mesh filename="eddie_meshes/kelo_base.stl"/>
      </geometry>
      <material name="light_gray">
        <color rgba="0.5 0.5 0.5 1.0"/>
      </material>
    </visual>
    <collision>
      <geometry>
        <!-- <box size="0.622 0.659 0.308" /> -->
        <mesh filename="eddie_meshes/kelo_base.stl"/>
      </geometry>
    </collision>
    <inertial>
      <mass value="1.0"/>
      <inertia ixx="0" ixy="0" ixz="0" iyy="0" iyz="0" izz="0"/>
    </inertial>
  </link>
  <link name="eddie_torso_link">
    <visual>
      <origin rpy="0 0 0" xyz="0 0 0"/>
      <geometry>
        <mesh filename="eddie_meshes/kelo_torso.stl"/>
      </geometry>
      <material name="metallic_silver">
        <color rgba="0.7 0.7 0.7 1.0"/>
      </material>
    </visual>
    <collision>
      <geometry>
        <mesh filename="eddie_meshes/kelo_torso.stl"/>
      </geometry>
    </collision>
    <inertial>
      <mass value="1.0"/>
      <inertia ixx="0" ixy="0" ixz="0" iyy="0" iyz="0" izz="0"/>
    </inertial>
  </link>
  <link name="eddie_left_arm_attachment_link"/>
  <link name="eddie_right_arm_attachment_link"/>
  <!-- Links -->
  <link name="eddie_front_left_struct_attachment_link">
    <visual>
      <origin rpy="0 0 0" xyz="0 0 0"/>
      <geometry>
        <mesh filename="eddie_meshes/kelo_drive_attachments.stl"/>
      </geometry>
      <material name="metallic_silver">
        <color rgba="0.7 0.7 0.7 1.0"/>
      </material>
    </visual>
    <collision>
      <geometry>
        <mesh filename="eddie_meshes/kelo_drive_attachments.stl"/>
      </geometry>
    </collision>
    <inertial>
      <mass value="1.0"/>
      <inertia ixx="0" ixy="0" ixz="0" iyy="0" iyz="0" izz="0"/>
    </inertial>
  </link>
  <link name="eddie_front_left_struct_link">
    <visual>
      <origin rpy="0 0 0" xyz="0 0 0"/>
      <geometry>
        <mesh filename="eddie_meshes/kelo_drive.stl"/>
      </geometry>
      <material name="metallic_silver">
        <color rgba="0.7 0.7 0.7 1.0"/>
      </material>
    </visual>
    <collision>
      <geometry>
        <mesh filename="eddie_meshes/kelo_drive.stl"/>
      </geometry>
    </collision>
    <inertial>
      <mass value="1.0"/>
      <inertia ixx="0" ixy="0" ixz="0" iyy="0" iyz="0" izz="0"/>
    </inertial>
  </link>
  <!-- Links -->
  <link name="eddie_front_left_right_wheel_link">
    <visual>
      <origin rpy="0 0 0" xyz="0 0 0"/>
      <geometry>
        <mesh filename="eddie_meshes/hub_wheel.stl"/>
      </geometry>
      <material name="black">
        <color rgba="0 0 0 1.0"/>
      </material>
    </visual>
    <collision>
      <geometry>
        <mesh filename="eddie_meshes/hub_wheel.stl"/>
      </geometry>
    </collision>
    <inertial>
      <mass value="1.0"/>
      <inertia ixx="0" ixy="0" ixz="0" iyy="0" iyz="0" izz="0"/>
    </inertial>
  </link>
  <!-- Links -->
  <link name="eddie_front_left_left_wheel_link">
    <visual>
      <origin rpy="0 0 0" xyz="0 0 0"/>
      <geometry>
        <mesh filename="eddie_meshes/hub_wheel.stl"/>
      </geometry>
      <material name="black">
        <color rgba="0 0 0 1.0"/>
      </material>
    </visual>
    <collision>
      <geometry>
        <mesh filename="eddie_meshes/hub_wheel.stl"/>
      </geometry>
    </collision>
    <inertial>
      <mass value="1.0"/>
      <inertia ixx="0" ixy="0" ixz="0" iyy="0" iyz="0" izz="0"/>
    </inertial>
  </link>
  <!-- Joints -->
  <joint name="eddie_front_left_struct_to_attachment_joint" type="continuous">
    <parent link="eddie_front_left_struct_attachment_link"/>
    <child link="eddie_front_left_struct_link"/>
    <origin rpy="0 0 1.5708" xyz="-0.0100 -0.0006 -0.0641"/>
    <axis xyz="0 0 1"/>
  </joint>
  <joint name="eddie_front_left_eddie_front_left_left_wheel_joint" type="continuous">
    <parent link="eddie_front_left_struct_link"/>
    <child link="eddie_front_left_left_wheel_link"/>
    <origin rpy="1.5708 0 0" xyz="0.0008 0.0407 -0.0366"/>
    <axis xyz="0 0 1"/>
  </joint>
  <joint name="eddie_front_left_eddie_front_left_right_wheel_joint" type="continuous">
    <parent link="eddie_front_left_struct_link"/>
    <child link="eddie_front_left_right_wheel_link"/>
    <origin rpy="-1.5708 0 0" xyz="0.0008 -0.0403 -0.0366"/>
    <axis xyz="0 0 1"/>
  </joint>
  <!-- Links -->
  <link name="eddie_rear_left_struct_attachment_link">
    <visual>
      <origin rpy="0 0 0" xyz="0 0 0"/>
      <geometry>
        <mesh filename="eddie_meshes/kelo_drive_attachments.stl"/>
      </geometry>
      <material name="metallic_silver">
        <color rgba="0.7 0.7 0.7 1.0"/>
      </material>
    </visual>
    <collision>
      <geometry>
        <mesh filename="eddie_meshes/kelo_drive_attachments.stl"/>
      </geometry>
    </collision>
    <inertial>
      <mass value="1.0"/>
      <inertia ixx="0" ixy="0" ixz="0" iyy="0" iyz="0" izz="0"/>
    </inertial>
  </link>
  <link name="eddie_rear_left_struct_link">
    <visual>
      <origin rpy="0 0 0" xyz="0 0 0"/>
      <geometry>
        <mesh filename="eddie_meshes/kelo_drive.stl"/>
      </geometry>
      <material name="metallic_silver">
        <color rgba="0.7 0.7 0.7 1.0"/>
      </material>
    </visual>
    <collision>
      <geometry>
        <mesh filename="eddie_meshes/kelo_drive.stl"/>
      </geometry>
    </collision>
    <inertial>
      <mass value="1.0"/>
      <inertia ixx="0" ixy="0" ixz="0" iyy="0" iyz="0" izz="0"/>
    </inertial>
  </link>
  <!-- Links -->
  <link name="eddie_rear_left_right_wheel_link">
    <visual>
      <origin rpy="0 0 0" xyz="0 0 0"/>
      <geometry>
        <mesh filename="eddie_meshes/hub_wheel.stl"/>
      </geometry>
      <material name="black">
        <color rgba="0 0 0 1.0"/>
      </material>
    </visual>
    <collision>
      <geometry>
        <mesh filename="eddie_meshes/hub_wheel.stl"/>
      </geometry>
    </collision>
    <inertial>
      <mass value="1.0"/>
      <inertia ixx="0" ixy="0" ixz="0" iyy="0" iyz="0" izz="0"/>
    </inertial>
  </link>
  <!-- Links -->
  <link name="eddie_rear_left_left_wheel_link">
    <visual>
      <origin rpy="0 0 0" xyz="0 0 0"/>
      <geometry>
        <mesh filename="eddie_meshes/hub_wheel.stl"/>
      </geometry>
      <material name="black">
        <color rgba="0 0 0 1.0"/>
      </material>
    </visual>
    <collision>
      <geometry>
        <mesh filename="eddie_meshes/hub_wheel.stl"/>
      </geometry>
    </collision>
    <inertial>
      <mass value="1.0"/>
      <inertia ixx="0" ixy="0" ixz="0" iyy="0" iyz="0" izz="0"/>
    </inertial>
  </link>
  <!-- Joints -->
  <joint name="eddie_rear_left_struct_to_attachment_joint" type="continuous">
    <parent link="eddie_rear_left_struct_attachment_link"/>
    <child link="eddie_rear_left_struct_link"/>
    <origin rpy="0 0 1.5708" xyz="-0.0100 -0.0006 -0.0641"/>
    <axis xyz="0 0 1"/>
  </joint>
  <joint name="eddie_rear_left_eddie_rear_left_left_wheel_joint" type="continuous">
    <parent link="eddie_rear_left_struct_link"/>
    <child link="eddie_rear_left_left_wheel_link"/>
    <origin rpy="1.5708 0 0" xyz="0.0008 0.0407 -0.0366"/>
    <axis xyz="0 0 1"/>
  </joint>
  <joint name="eddie_rear_left_eddie_rear_left_right_wheel_joint" type="continuous">
    <parent link="eddie_rear_left_struct_link"/>
    <child link="eddie_rear_left_right_wheel_link"/>
    <origin rpy="-1.5708 0 0" xyz="0.0008 -0.0403 -0.0366"/>
    <axis xyz="0 0 1"/>
  </joint>
  <!-- Links -->
  <link name="eddie_rear_right_struct_attachment_link">
    <visual>
      <origin rpy="0 0 0" xyz="0 0 0"/>
      <geometry>
        <mesh filename="eddie_meshes/kelo_drive_attachments.stl"/>
      </geometry>
      <material name="metallic_silver">
        <color rgba="0.7 0.7 0.7 1.0"/>
      </material>
    </visual>
    <collision>
      <geometry>
        <mesh filename="eddie_meshes/kelo_drive_attachments.stl"/>
      </geometry>
    </collision>
    <inertial>
      <mass value="1.0"/>
      <inertia ixx="0" ixy="0" ixz="0" iyy="0" iyz="0" izz="0"/>
    </inertial>
  </link>
  <link name="eddie_rear_right_struct_link">
    <visual>
      <origin rpy="0 0 0" xyz="0 0 0"/>
      <geometry>
        <mesh filename="eddie_meshes/kelo_drive.stl"/>
      </geometry>
      <material name="metallic_silver">
        <color rgba="0.7 0.7 0.7 1.0"/>
      </material>
    </visual>
    <collision>
      <geometry>
        <mesh filename="eddie_meshes/kelo_drive.stl"/>
      </geometry>
    </collision>
    <inertial>
      <mass value="1.0"/>
      <inertia ixx="0" ixy="0" ixz="0" iyy="0" iyz="0" izz="0"/>
    </inertial>
  </link>
  <!-- Links -->
  <link name="eddie_rear_right_right_wheel_link">
    <visual>
      <origin rpy="0 0 0" xyz="0 0 0"/>
      <geometry>
        <mesh filename="eddie_meshes/hub_wheel.stl"/>
      </geometry>
      <material name="black">
        <color rgba="0 0 0 1.0"/>
      </material>
    </visual>
    <collision>
      <geometry>
        <mesh filename="eddie_meshes/hub_wheel.stl"/>
      </geometry>
    </collision>
    <inertial>
      <mass value="1.0"/>
      <inertia ixx="0" ixy="0" ixz="0" iyy="0" iyz="0" izz="0"/>
    </inertial>
  </link>
  <!-- Links -->
  <link name="eddie_rear_right_left_wheel_link">
    <visual>
      <origin rpy="0 0 0" xyz="0 0 0"/>
      <geometry>
        <mesh filename="eddie_meshes/hub_wheel.stl"/>
      </geometry>
      <material name="black">
        <color rgba="0 0 0 1.0"/>
      </material>
    </visual>
    <collision>
      <geometry>
        <mesh filename="eddie_meshes/hub_wheel.stl"/>
      </geometry>
    </collision>
    <inertial>
      <mass value="1.0"/>
      <inertia ixx="0" ixy="0" ixz="0" iyy="0" iyz="0" izz="0"/>
    </inertial>
  </link>
  <!-- Joints -->
  <joint name="eddie_rear_right_struct_to_attachment_joint" type="continuous">
    <parent link="eddie_rear_right_struct_attachment_link"/>
    <child link="eddie_rear_right_struct_link"/>
    <origin rpy="0 0 1.5708" xyz="-0.0100 -0.0006 -0.0641"/>
    <axis xyz="0 0 1"/>
  </joint>
  <joint name="eddie_rear_right_eddie_rear_right_left_wheel_joint" type="continuous">
    <parent link="eddie_rear_right_struct_link"/>
    <child link="eddie_rear_right_left_wheel_link"/>
    <origin rpy="1.5708 0 0" xyz="0.0008 0.0407 -0.0366"/>
    <axis xyz="0 0 1"/>
  </joint>
  <joint name="eddie_rear_right_eddie_rear_right_right_wheel_joint" type="continuous">
    <parent link="eddie_rear_right_struct_link"/>
    <child link="eddie_rear_right_right_wheel_link"/>
    <origin rpy="-1.5708 0 0" xyz="0.0008 -0.0403 -0.0366"/>
    <axis xyz="0 0 1"/>
  </joint>
  <!-- Links -->
  <link name="eddie_front_right_struct_attachment_link">
    <visual>
      <origin rpy="0 0 0" xyz="0 0 0"/>
      <geometry>
        <mesh filename="eddie_meshes/kelo_drive_attachments.stl"/>
      </geometry>
      <material name="metallic_silver">
        <color rgba="0.7 0.7 0.7 1.0"/>
      </material>
    </visual>
    <collision>
      <geometry>
        <mesh filename="eddie_meshes/kelo_drive_attachments.stl"/>
      </geometry>
    </collision>
    <inertial>
      <mass value="1.0"/>
      <inertia ixx="0" ixy="0" ixz="0" iyy="0" iyz="0" izz="0"/>
    </inertial>
  </link>
  <link name="eddie_front_right_struct_link">
    <visual>
      <origin rpy="0 0 0" xyz="0 0 0"/>
      <geometry>
        <mesh filename="eddie_meshes/kelo_drive.stl"/>
      </geometry>
      <material name="metallic_silver">
        <color rgba="0.7 0.7 0.7 1.0"/>
      </material>
    </visual>
    <collision>
      <geometry>
        <mesh filename="eddie_meshes/kelo_drive.stl"/>
      </geometry>
    </collision>
    <inertial>
      <mass value="1.0"/>
      <inertia ixx="0" ixy="0" ixz="0" iyy="0" iyz="0" izz="0"/>
    </inertial>
  </link>
  <!-- Links -->
  <link name="eddie_front_right_right_wheel_link">
    <visual>
      <origin rpy="0 0 0" xyz="0 0 0"/>
      <geometry>
        <mesh filename="eddie_meshes/hub_wheel.stl"/>
      </geometry>
      <material name="black">
        <color rgba="0 0 0 1.0"/>
      </material>
    </visual>
    <collision>
      <geometry>
        <mesh filename="eddie_meshes/hub_wheel.stl"/>
      </geometry>
    </collision>
    <inertial>
      <mass value="1.0"/>
      <inertia ixx="0" ixy="0" ixz="0" iyy="0" iyz="0" izz="0"/>
    </inertial>
  </link>
  <!-- Links -->
  <link name="eddie_front_right_left_wheel_link">
    <visual>
      <origin rpy="0 0 0" xyz="0 0 0"/>
      <geometry>
        <mesh filename="eddie_meshes/hub_wheel.stl"/>
      </geometry>
      <material name="black">
        <color rgba="0 0 0 1.0"/>
      </material>
    </visual>
    <collision>
      <geometry>
        <mesh filename="eddie_meshes/hub_wheel.stl"/>
      </geometry>
    </collision>
    <inertial>
      <mass value="1.0"/>
      <inertia ixx="0" ixy="0" ixz="0" iyy="0" iyz="0" izz="0"/>
    </inertial>
  </link>
  <!-- Joints -->
  <joint name="eddie_front_right_struct_to_attachment_joint" type="continuous">
    <parent link="eddie_front_right_struct_attachment_link"/>
    <child link="eddie_front_right_struct_link"/>
    <origin rpy="0 0 1.5708" xyz="-0.0100 -0.0006 -0.0641"/>
    <axis xyz="0 0 1"/>
  </joint>
  <joint name="eddie_front_right_eddie_front_right_left_wheel_joint" type="continuous">
    <parent link="eddie_front_right_struct_link"/>
    <child link="eddie_front_right_left_wheel_link"/>
    <origin rpy="1.5708 0 0" xyz="0.0008 0.0407 -0.0366"/>
    <axis xyz="0 0 1"/>
  </joint>
  <joint name="eddie_front_right_eddie_front_right_right_wheel_joint" type="continuous">
    <parent link="eddie_front_right_struct_link"/>
    <child link="eddie_front_right_right_wheel_link"/>
    <origin rpy="-1.5708 0 0" xyz="0.0008 -0.0403 -0.0366"/>
    <axis xyz="0 0 1"/>
  </joint>
  <!-- Joints -->
  <joint name="eddie_base_footprint_joint" type="fixed">
    <parent link="eddie_base_footprint"/>
    <child link="eddie_base_link"/>
    <origin rpy="0 0 0" xyz="0 0 0.2164"/>
  </joint>
  <joint name="eddie_base_torso_joint" type="fixed">
    <parent link="eddie_base_link"/>
    <child link="eddie_torso_link"/>
    <origin rpy="0 0 1.5708" xyz="-0.1738 0.0003 0.4184"/>
  </joint>
  <joint name="eddie_front_left_joint" type="fixed">
    <parent link="eddie_base_link"/>
    <child link="eddie_front_left_struct_attachment_link"/>
    <origin rpy="0 0 1.5708" xyz="0.2078 0.1880 -0.0632"/>
  </joint>
  <joint name="eddie_rear_left_joint" type="fixed">
    <parent link="eddie_base_link"/>
    <child link="eddie_rear_left_struct_attachment_link"/>
    <origin rpy="0 0 1.5708" xyz="-0.2078 0.1880 -0.0632"/>
  </joint>
  <joint name="eddie_rear_right_joint" type="fixed">
    <parent link="eddie_base_link"/>
    <child link="eddie_rear_right_struct_attachment_link"/>
    <origin rpy="0 0 -1.5708" xyz="-0.2078 -0.1880 -0.0632"/>
  </joint>
  <joint name="eddie_front_right_joint" type="fixed">
    <parent link="eddie_base_link"/>
    <child link="eddie_front_right_struct_attachment_link"/>
    <origin rpy="0 0 -1.5708" xyz="0.2078 -0.1880 -0.0632"/>
  </joint>
  <joint name="eddie_left_arm_attachment_joint" type="fixed">
    <parent link="eddie_torso_link"/>
    <child link="eddie_left_arm_attachment_link"/>
    <origin rpy="0 0.09 -0.7783" xyz="0.0676 -0.0236 0.1160"/>
  </joint>
  <joint name="eddie_right_arm_attachment_joint" type="fixed">
    <parent link="eddie_torso_link"/>
    <child link="eddie_right_arm_attachment_link"/>
    <origin rpy="0 0.09 -2.3632" xyz="-0.0676 -0.0236 0.1160"/>
  </joint>
  <!-- ros2 control include -->
  <!-- <xacro:include filename="$(find kortex_description)/arms/gen3/${dof}dof/urdf/kortex.ros2_control.xacro" />
    <xacro:kortex_ros2_control
      name="${prefix}KortexMultiInterfaceHardware" prefix="${prefix}"
      use_fake_hardware="${use_fake_hardware}"
      fake_sensor_commands="${fake_sensor_commands}"
      sim_gazebo="${sim_gazebo}"
      sim_ignition="${sim_ignition}"
      sim_isaac="${sim_isaac}"
      isaac_joint_commands="${isaac_joint_commands}"
      isaac_joint_states="${isaac_joint_states}"
      tf_prefix=""
      initial_positions="${initial_positions}"
      robot_ip="${robot_ip}"
      username="${username}"
      password="${password}"
      port="${port}"
      port_realtime="${port_realtime}"
      session_inactivity_timeout_ms="${session_inactivity_timeout_ms}"
      connection_inactivity_timeout_ms="${connection_inactivity_timeout_ms}"
      use_internal_bus_gripper_comm="${use_internal_bus_gripper_comm}"
      gripper_max_velocity="${gripper_max_velocity}"
      gripper_max_force="${gripper_max_force}"
      gripper_joint_name="${gripper_joint_name}"/> -->
  <joint name="eddie_left_arm_base_joint" type="fixed">
    <origin rpy="1.5708 -1.5708 1.5708" xyz="0.01549 0 0"/>
    <parent link="eddie_left_arm_attachment_link"/>
    <child link="eddie_left_arm_base_link"/>
  </joint>
  <link name="eddie_left_arm_base_link">
    <inertial>
      <origin rpy="0 0 0" xyz="-0.000648 -0.000166 0.084487"/>
      <mass value="1.697"/>
      <inertia ixx="0.004622" ixy="9E-06" ixz="6E-05" iyy="0.004495" iyz="9E-06" izz="0.002079"/>
    </inertial>
    <visual>
      <origin rpy="0 0 0" xyz="0 0 0"/>
      <geometry>
        <mesh filename="eddie_meshes/base_link.dae"/>
      </geometry>
      <material name="">
        <color rgba="0.75294 0.75294 0.75294 1"/>
      </material>
    </visual>
    <collision>
      <origin rpy="0 0 0" xyz="0 0 0"/>
      <geometry>
        <mesh filename="eddie_meshes/base_link.dae"/>
      </geometry>
    </collision>
  </link>
  <link name="eddie_left_arm_shoulder_link">
    <inertial>
      <origin rpy="0 0 0" xyz="-2.3E-05 -0.010364 -0.07336"/>
      <mass value="1.3773"/>
      <inertia ixx="0.00457" ixy="1E-06" ixz="2E-06" iyy="0.004831" iyz="0.000448" izz="0.001409"/>
    </inertial>
    <visual>
      <origin rpy="0 0 0" xyz="0 0 0"/>
      <geometry>
        <mesh filename="eddie_meshes/shoulder_link.dae"/>
      </geometry>
      <material name="">
        <color rgba="0.75294 0.75294 0.75294 1"/>
      </material>
    </visual>
    <collision>
      <origin rpy="0 0 0" xyz="0 0 0"/>
      <geometry>
        <mesh filename="eddie_meshes/shoulder_link.dae"/>
      </geometry>
    </collision>
  </link>
  <joint name="eddie_left_arm_joint_1" type="continuous">
    <origin rpy="3.1416 2.7629E-18 -4.9305E-36" xyz="0 0 0.15643"/>
    <parent link="eddie_left_arm_base_link"/>
    <child link="eddie_left_arm_shoulder_link"/>
    <axis xyz="0 0 1"/>
    <limit effort="39" velocity="1.3963"/>
  </joint>
  <link name="eddie_left_arm_half_arm_1_link">
    <inertial>
      <origin rpy="0 0 0" xyz="-4.4E-05 -0.09958 -0.013278"/>
      <mass value="1.1636"/>
      <inertia ixx="0.011088" ixy="5E-06" ixz="0" iyy="0.001072" iyz="-0.000691" izz="0.011255"/>
    </inertial>
    <visual>
      <origin rpy="0 0 0" xyz="0 0 0"/>
      <geometry>
        <mesh filename="eddie_meshes/half_arm_1_link.dae"/>
      </geometry>
      <material name="">
        <color rgba="0.75294 0.75294 0.75294 1"/>
      </material>
    </visual>
    <collision>
      <origin rpy="0 0 0" xyz="0 0 0"/>
      <geometry>
        <mesh filename="eddie_meshes/half_arm_1_link.dae"/>
      </geometry>
    </collision>
  </link>
  <joint name="eddie_left_arm_joint_2" type="revolute">
    <origin rpy="1.5708 2.1343E-17 -1.1102E-16" xyz="0 0.005375 -0.12838"/>
    <parent link="eddie_left_arm_shoulder_link"/>
    <child link="eddie_left_arm_half_arm_1_link"/>
    <axis xyz="0 0 1"/>
    <limit effort="39" lower="-2.24" upper="2.24" velocity="1.3963"/>
  </joint>
  <link name="eddie_left_arm_half_arm_2_link">
    <inertial>
      <origin rpy="0 0 0" xyz="-4.4E-05 -0.006641 -0.117892"/>
      <mass value="1.1636"/>
      <inertia ixx="0.010932" ixy="0" ixz="-7E-06" iyy="0.011127" iyz="0.000606" izz="0.001043"/>
    </inertial>
    <visual>
      <origin rpy="0 0 0" xyz="0 0 0"/>
      <geometry>
        <mesh filename="eddie_meshes/half_arm_2_link.dae"/>
      </geometry>
      <material name="">
        <color rgba="0.75294 0.75294 0.75294 1"/>
      </material>
    </visual>
    <collision>
      <origin rpy="0 0 0" xyz="0 0 0"/>
      <geometry>
        <mesh filename="eddie_meshes/half_arm_2_link.dae"/>
      </geometry>
    </collision>
  </link>
  <joint name="eddie_left_arm_joint_3" type="continuous">
    <origin rpy="-1.5708 1.2326E-32 -2.9122E-16" xyz="0 -0.21038 -0.006375"/>
    <parent link="eddie_left_arm_half_arm_1_link"/>
    <child link="eddie_left_arm_half_arm_2_link"/>
    <axis xyz="0 0 1"/>
    <limit effort="39" velocity="1.3963"/>
  </joint>
  <link name="eddie_left_arm_forearm_link">
    <inertial>
      <origin rpy="0 0 0" xyz="-1.8E-05 -0.075478 -0.015006"/>
      <mass value="0.9302"/>
      <inertia ixx="0.008147" ixy="-1E-06" ixz="0" iyy="0.000631" iyz="-0.0005" izz="0.008316"/>
    </inertial>
    <visual>
      <origin rpy="0 0 0" xyz="0 0 0"/>
      <geometry>
        <mesh filename="eddie_meshes/forearm_link.dae"/>
      </geometry>
      <material name="">
        <color rgba="0.75294 0.75294 0.75294 1"/>
      </material>
    </visual>
    <collision>
      <origin rpy="0 0 0" xyz="0 0 0"/>
      <geometry>
        <mesh filename="eddie_meshes/forearm_link.dae"/>
      </geometry>
    </collision>
  </link>
  <joint name="eddie_left_arm_joint_4" type="revolute">
    <origin rpy="1.5708 -6.6954E-17 -1.6653E-16" xyz="0 0.006375 -0.21038"/>
    <parent link="eddie_left_arm_half_arm_2_link"/>
    <child link="eddie_left_arm_forearm_link"/>
    <axis xyz="0 0 1"/>
    <limit effort="39" lower="-2.57" upper="2.57" velocity="1.3963"/>
  </joint>
  <link name="eddie_left_arm_spherical_wrist_1_link">
    <inertial>
      <origin rpy="0 0 0" xyz="1E-06 -0.009432 -0.063883"/>
      <mass value="0.6781"/>
      <inertia ixx="0.001596" ixy="0" ixz="0" iyy="0.001607" iyz="0.000256" izz="0.000399"/>
    </inertial>
    <visual>
      <origin rpy="0 0 0" xyz="0 0 0"/>
      <geometry>
        <mesh filename="eddie_meshes/spherical_wrist_1_link.dae"/>
      </geometry>
      <material name="">
        <color rgba="0.75294 0.75294 0.75294 1"/>
      </material>
    </visual>
    <collision>
      <origin rpy="0 0 0" xyz="0 0 0"/>
      <geometry>
        <mesh filename="eddie_meshes/spherical_wrist_1_link.dae"/>
      </geometry>
    </collision>
  </link>
  <joint name="eddie_left_arm_joint_5" type="continuous">
    <origin rpy="-1.5708 2.2204E-16 -6.373E-17" xyz="0 -0.20843 -0.006375"/>
    <parent link="eddie_left_arm_forearm_link"/>
    <child link="eddie_left_arm_spherical_wrist_1_link"/>
    <axis xyz="0 0 1"/>
    <limit effort="9" velocity="1.2218"/>
  </joint>
  <link name="eddie_left_arm_spherical_wrist_2_link">
    <inertial>
      <origin rpy="0 0 0" xyz="1E-06 -0.045483 -0.00965"/>
      <mass value="0.6781"/>
      <inertia ixx="0.001641" ixy="0" ixz="0" iyy="0.00041" iyz="-0.000278" izz="0.001641"/>
    </inertial>
    <visual>
      <origin rpy="0 0 0" xyz="0 0 0"/>
      <geometry>
        <mesh filename="eddie_meshes/spherical_wrist_2_link.dae"/>
      </geometry>
      <material name="">
        <color rgba="0.75294 0.75294 0.75294 1"/>
      </material>
    </visual>
    <collision>
      <origin rpy="0 0 0" xyz="0 0 0"/>
      <geometry>
        <mesh filename="eddie_meshes/spherical_wrist_2_link.dae"/>
      </geometry>
    </collision>
  </link>
  <joint name="eddie_left_arm_joint_6" type="revolute">
    <origin rpy="1.5708 9.2076E-28 -8.2157E-15" xyz="0 0.00017505 -0.10593"/>
    <parent link="eddie_left_arm_spherical_wrist_1_link"/>
    <child link="eddie_left_arm_spherical_wrist_2_link"/>
    <axis xyz="0 0 1"/>
    <limit effort="9" lower="-2.09" upper="2.09" velocity="1.2218"/>
  </joint>
  <link name="eddie_left_arm_bracelet_link">
    <inertial>
      <origin rpy="0 0 0" xyz="0.000281 0.011402 -0.029798"/>
      <mass value="0.5"/>
      <inertia ixx="0.000587" ixy="3E-06" ixz="3E-06" iyy="0.000369" iyz="-0.000118" izz="0.000609"/>
    </inertial>
    <visual>
      <origin rpy="0 0 0" xyz="0 0 0"/>
      <geometry>
        <mesh filename="eddie_meshes/bracelet_with_vision_link.dae"/>
      </geometry>
      <material name="">
        <color rgba="0.75294 0.75294 0.75294 1"/>
      </material>
    </visual>
    <collision>
      <origin rpy="0 0 0" xyz="0 0 0"/>
      <geometry>
        <mesh filename="eddie_meshes/bracelet_with_vision_link.dae"/>
      </geometry>
    </collision>
  </link>
  <joint name="eddie_left_arm_joint_7" type="continuous">
    <origin rpy="-1.5708 -5.5511E-17 9.6396E-17" xyz="0 -0.10593 -0.00017505"/>
    <parent link="eddie_left_arm_spherical_wrist_2_link"/>
    <child link="eddie_left_arm_bracelet_link"/>
    <axis xyz="0 0 1"/>
    <limit effort="9" velocity="1.2218"/>
  </joint>
  <link name="eddie_left_arm_end_effector_link"/>
  <joint name="eddie_left_arm_end_effector" type="fixed">
    <origin rpy="3.14159265358979 1.09937075168372E-32 0" xyz="0 0 -0.0615250000000001"/>
    <parent link="eddie_left_arm_bracelet_link"/>
    <child link="eddie_left_arm_end_effector_link"/>
    <axis xyz="0 0 0"/>
  </joint>
  <link name="eddie_left_arm_camera_link"/>
  <joint name="eddie_left_arm_camera_module" type="fixed">
    <origin rpy="3.141592653589793 3.141592653589793 0" xyz="0 0.05639 -0.00305"/>
    <parent link="eddie_left_arm_end_effector_link"/>
    <child link="eddie_left_arm_camera_link"/>
  </joint>
  <link name="eddie_left_arm_camera_depth_frame"/>
  <joint name="eddie_left_arm_depth_module" type="fixed">
    <origin rpy="3.141592653589793 3.141592653589793 0" xyz="0.0275 0.066 -0.00305"/>
    <parent link="eddie_left_arm_end_effector_link"/>
    <child link="eddie_left_arm_camera_depth_frame"/>
  </joint>
  <link name="eddie_left_arm_camera_color_frame"/>
  <joint name="eddie_left_arm_color_module" type="fixed">
    <origin rpy="3.141592653589793 3.141592653589793 0" xyz="0 0.05639 -0.00305"/>
    <parent link="eddie_left_arm_end_effector_link"/>
    <child link="eddie_left_arm_camera_color_frame"/>
  </joint>
  <link name="eddie_left_arm_robotiq_85_base_link">
    <visual>
      <geometry>
        <mesh filename="eddie_meshes/visual/2f_85/robotiq_base.dae"/>
      </geometry>
    </visual>
    <collision>
      <geometry>
        <mesh filename="eddie_meshes/collision/2f_85/robotiq_base.stl"/>
      </geometry>
    </collision>
    <inertial>
      <origin rpy="0 0 0" xyz="0.0 2.274e-05 0.03232288"/>
      <mass value="6.6320197e-01"/>
      <inertia ixx="5.1617816e-04" ixy="2.936e-8" ixz="0.0" iyy="5.8802208e-04" iyz="-3.2296e-7" izz="3.9462776e-04"/>
    </inertial>
  </link>
  <link name="eddie_left_arm_robotiq_85_left_knuckle_link">
    <visual>
      <geometry>
        <mesh filename="eddie_meshes/visual/2f_85/left_knuckle.dae"/>
      </geometry>
    </visual>
    <collision>
      <geometry>
        <mesh filename="eddie_meshes/collision/2f_85/left_knuckle.stl"/>
      </geometry>
    </collision>
    <inertial>
      <origin rpy="0 0 0" xyz="0.01213197 0.0002 -0.00058647"/>
      <mass value="1.384773208e-02"/>
      <inertia ixx="3.5232e-7" ixy="0.0" ixz="1.1744e-7" iyy="2.31944e-6" iyz="0" izz="2.23136e-6"/>
    </inertial>
  </link>
  <link name="eddie_left_arm_robotiq_85_right_knuckle_link">
    <visual>
      <geometry>
        <mesh filename="eddie_meshes/visual/2f_85/right_knuckle.dae"/>
      </geometry>
    </visual>
    <collision>
      <geometry>
        <mesh filename="eddie_meshes/collision/2f_85/right_knuckle.stl"/>
      </geometry>
    </collision>
    <inertial>
      <origin rpy="0 0 0" xyz="-0.01213197 0.0002 -0.00058647"/>
      <mass value="1.384773208e-02"/>
      <inertia ixx="3.5232e-7" ixy="0.0" ixz="-1.1744e-7" iyy="2.31944e-6" iyz="0.0" izz="2.23136e-6"/>
    </inertial>
  </link>
  <link name="eddie_left_arm_robotiq_85_left_finger_link">
    <visual>
      <geometry>
        <mesh filename="eddie_meshes/visual/2f_85/left_finger.dae"/>
      </geometry>
    </visual>
    <collision>
      <geometry>
        <mesh filename="eddie_meshes/collision/2f_85/left_finger.stl"/>
      </geometry>
    </collision>
    <inertial>
      <origin rpy="0 0 0" xyz="0.00346899 -0.00079447 0.01867121"/>
      <mass value="4.260376752e-02"/>
      <inertia ixx="1.385792000000000e-05" ixy="0.0" ixz="-2.17264e-06" iyy="1.183208e-05" iyz="0.0" izz="5.19672e-06"/>
    </inertial>
  </link>
  <link name="eddie_left_arm_robotiq_85_right_finger_link">
    <visual>
      <geometry>
        <mesh filename="eddie_meshes/visual/2f_85/right_finger.dae"/>
      </geometry>
    </visual>
    <collision>
      <geometry>
        <mesh filename="eddie_meshes/collision/2f_85/right_finger.stl"/>
      </geometry>
    </collision>
    <inertial>
      <origin rpy="0 0 0" xyz="-0.00346899 -5.53e-06 0.01867121"/>
      <mass value="4.260376752000000e-02"/>
      <inertia ixx="1.385792e-05" ixy="0.0" ixz="2.17264e-06" iyy="1.183208e-05" iyz="0.0" izz="5.19672e-06"/>
    </inertial>
  </link>
  <link name="eddie_left_arm_robotiq_85_left_inner_knuckle_link">
    <visual>
      <geometry>
        <mesh filename="eddie_meshes/visual/2f_85/left_inner_knuckle.dae"/>
      </geometry>
    </visual>
    <collision>
      <geometry>
        <mesh filename="eddie_meshes/collision/2f_85/left_inner_knuckle.stl"/>
      </geometry>
    </collision>
    <inertial>
      <origin rpy="0 0 0" xyz="0.01897699 0.00015001 0.02247101"/>
      <mass value="2.969376448e-02"/>
      <inertia ixx="9.57136e-06" ixy="0.0" ixz="-3.93424e-06" iyy="8.69056e-06" iyz="0.0" izz="8.19144e-06"/>
    </inertial>
  </link>
  <link name="eddie_left_arm_robotiq_85_right_inner_knuckle_link">
    <visual>
      <geometry>
        <mesh filename="eddie_meshes/visual/2f_85/right_inner_knuckle.dae"/>
      </geometry>
    </visual>
    <collision>
      <geometry>
        <mesh filename="eddie_meshes/collision/2f_85/right_inner_knuckle.stl"/>
      </geometry>
    </collision>
    <inertial>
      <origin rpy="0 0 0" xyz="-0.01926824 5.001e-05 0.02222178"/>
      <mass value="2.969376448e-02"/>
      <inertia ixx="9.42456e-06" ixy="0.0" ixz="3.9636e-06" iyy="8.69056e-06" iyz="0.0" izz="8.33824e-06"/>
    </inertial>
  </link>
  <link name="eddie_left_arm_robotiq_85_left_finger_tip_link">
    <visual>
      <geometry>
        <mesh filename="eddie_meshes/visual/2f_85/left_finger_tip.dae"/>
      </geometry>
    </visual>
    <collision>
      <geometry>
        <mesh filename="eddie_meshes/collision/2f_85/left_finger_tip.stl"/>
      </geometry>
      <surface>
        <friction>
          <ode>
            <mu1>100000.0</mu1>
            <mu2>100000.0</mu2>
          </ode>
        </friction>
        <contact>
          <ode>
            <kp>1e+5</kp>
            <kd>1</kd>
            <soft_cfm>0</soft_cfm>
            <soft_erp>0.2</soft_erp>
            <minDepth>0.002</minDepth>
            <maxVel>0</maxVel>
          </ode>
        </contact>
      </surface>
    </collision>
    <inertial>
      <origin rpy="0 0 0" xyz="-0.01456706 -0.0008 0.01649701"/>
      <mass value="4.268588744e-02"/>
      <inertia ixx="1.048152e-05" ixy="0.0" ixz="3.5232e-6" iyy="1.197888e-05" iyz="0.0" izz="4.22784e-06"/>
    </inertial>
  </link>
  <link name="eddie_left_arm_robotiq_85_right_finger_tip_link">
    <visual>
      <geometry>
        <mesh filename="eddie_meshes/visual/2f_85/right_finger_tip.dae"/>
      </geometry>
    </visual>
    <collision>
      <geometry>
        <mesh filename="eddie_meshes/collision/2f_85/right_finger_tip.stl"/>
      </geometry>
      <surface>
        <friction>
          <ode>
            <mu1>100000.0</mu1>
            <mu2>100000.0</mu2>
          </ode>
        </friction>
        <contact>
          <ode>
            <kp>1e+5</kp>
            <kd>1</kd>
            <soft_cfm>0</soft_cfm>
            <soft_erp>0.2</soft_erp>
            <minDepth>0.002</minDepth>
            <maxVel>0</maxVel>
          </ode>
        </contact>
      </surface>
    </collision>
    <inertial>
      <origin rpy="0 0 0" xyz="0.01456706 5e-05 0.01649701"/>
      <mass value="4.268588744e-02"/>
      <inertia ixx="1.048152e-05" ixy="0.0" ixz="-3.5232e-06" iyy="1.197888e-05" iyz="0.0" izz="4.22784e-06"/>
    </inertial>
  </link>
  <joint name="eddie_left_arm_robotiq_85_base_joint" type="fixed">
    <parent link="eddie_left_arm_end_effector_link"/>
    <child link="eddie_left_arm_robotiq_85_base_link"/>
    <origin rpy="0 0 0" xyz="0 0 0"/>
  </joint>
  <joint name="eddie_left_arm_robotiq_85_left_knuckle_joint" type="revolute">
    <parent link="eddie_left_arm_robotiq_85_base_link"/>
    <child link="eddie_left_arm_robotiq_85_left_knuckle_link"/>
    <axis xyz="0 -1 0"/>
    <origin rpy="0 0 0" xyz="0.03060114 0.0 0.05490452"/>
    <limit effort="50" lower="0.0" upper="0.8" velocity="0.5"/>
  </joint>
  <joint name="eddie_left_arm_robotiq_85_right_knuckle_joint" type="revolute">
    <parent link="eddie_left_arm_robotiq_85_base_link"/>
    <child link="eddie_left_arm_robotiq_85_right_knuckle_link"/>
    <axis xyz="0 -1 0"/>
    <origin rpy="0 0 0" xyz="-0.03060114 0.0 0.05490452"/>
    <limit effort="50" lower="-0.8" upper="0.0" velocity="0.5"/>
    <mimic joint="eddie_left_arm_robotiq_85_left_knuckle_joint" multiplier="-1"/>
  </joint>
  <joint name="eddie_left_arm_robotiq_85_left_finger_joint" type="fixed">
    <parent link="eddie_left_arm_robotiq_85_left_knuckle_link"/>
    <child link="eddie_left_arm_robotiq_85_left_finger_link"/>
    <origin rpy="0 0 0" xyz="0.03152616 0.0 -0.00376347"/>
  </joint>
  <joint name="eddie_left_arm_robotiq_85_right_finger_joint" type="fixed">
    <parent link="eddie_left_arm_robotiq_85_right_knuckle_link"/>
    <child link="eddie_left_arm_robotiq_85_right_finger_link"/>
    <origin rpy="0 0 0" xyz="-0.03152616 0.0 -0.00376347"/>
  </joint>
  <joint name="eddie_left_arm_robotiq_85_left_inner_knuckle_joint" type="continuous">
    <parent link="eddie_left_arm_robotiq_85_base_link"/>
    <child link="eddie_left_arm_robotiq_85_left_inner_knuckle_link"/>
    <axis xyz="0 -1 0"/>
    <origin rpy="0 0 0" xyz="0.0127 0.0 0.06142"/>
    <mimic joint="eddie_left_arm_robotiq_85_left_knuckle_joint"/>
  </joint>
  <joint name="eddie_left_arm_robotiq_85_right_inner_knuckle_joint" type="continuous">
    <parent link="eddie_left_arm_robotiq_85_base_link"/>
    <child link="eddie_left_arm_robotiq_85_right_inner_knuckle_link"/>
    <axis xyz="0 -1 0"/>
    <origin rpy="0 0 0" xyz="-0.0127 0.0 0.06142"/>
    <mimic joint="eddie_left_arm_robotiq_85_left_knuckle_joint" multiplier="-1"/>
  </joint>
  <joint name="eddie_left_arm_robotiq_85_left_finger_tip_joint" type="continuous">
    <parent link="eddie_left_arm_robotiq_85_left_finger_link"/>
    <child link="eddie_left_arm_robotiq_85_left_finger_tip_link"/>
    <axis xyz="0 -1 0"/>
    <origin rpy="0 0 0" xyz="0.00563134 0.0 0.04718515"/>
    <mimic joint="eddie_left_arm_robotiq_85_left_knuckle_joint" multiplier="-1"/>
  </joint>
  <joint name="eddie_left_arm_robotiq_85_right_finger_tip_joint" type="continuous">
    <parent link="eddie_left_arm_robotiq_85_right_finger_link"/>
    <child link="eddie_left_arm_robotiq_85_right_finger_tip_link"/>
    <axis xyz="0 -1 0"/>
    <origin rpy="0 0 0" xyz="-0.00563134 0.0 0.04718515"/>
    <mimic joint="eddie_left_arm_robotiq_85_left_knuckle_joint"/>
  </joint>
  <!-- ros2 control include -->
  <!-- <xacro:include filename="$(find kortex_description)/arms/gen3/${dof}dof/urdf/kortex.ros2_control.xacro" />
    <xacro:kortex_ros2_control
      name="${prefix}KortexMultiInterfaceHardware" prefix="${prefix}"
      use_fake_hardware="${use_fake_hardware}"
      fake_sensor_commands="${fake_sensor_commands}"
      sim_gazebo="${sim_gazebo}"
      sim_ignition="${sim_ignition}"
      sim_isaac="${sim_isaac}"
      isaac_joint_commands="${isaac_joint_commands}"
      isaac_joint_states="${isaac_joint_states}"
      tf_prefix=""
      initial_positions="${initial_positions}"
      robot_ip="${robot_ip}"
      username="${username}"
      password="${password}"
      port="${port}"
      port_realtime="${port_realtime}"
      session_inactivity_timeout_ms="${session_inactivity_timeout_ms}"
      connection_inactivity_timeout_ms="${connection_inactivity_timeout_ms}"
      use_internal_bus_gripper_comm="${use_internal_bus_gripper_comm}"
      gripper_max_velocity="${gripper_max_velocity}"
      gripper_max_force="${gripper_max_force}"
      gripper_joint_name="${gripper_joint_name}"/> -->
  <joint name="eddie_right_arm_base_joint" type="fixed">
    <origin rpy="1.5708 -1.5708 1.5708" xyz="0.01549 0 0"/>
    <parent link="eddie_right_arm_attachment_link"/>
    <child link="eddie_right_arm_base_link"/>
  </joint>
  <link name="eddie_right_arm_base_link">
    <inertial>
      <origin rpy="0 0 0" xyz="-0.000648 -0.000166 0.084487"/>
      <mass value="1.697"/>
      <inertia ixx="0.004622" ixy="9E-06" ixz="6E-05" iyy="0.004495" iyz="9E-06" izz="0.002079"/>
    </inertial>
    <visual>
      <origin rpy="0 0 0" xyz="0 0 0"/>
      <geometry>
        <mesh filename="eddie_meshes/base_link.dae"/>
      </geometry>
      <material name="">
        <color rgba="0.75294 0.75294 0.75294 1"/>
      </material>
    </visual>
    <collision>
      <origin rpy="0 0 0" xyz="0 0 0"/>
      <geometry>
        <mesh filename="eddie_meshes/base_link.dae"/>
      </geometry>
    </collision>
  </link>
  <link name="eddie_right_arm_shoulder_link">
    <inertial>
      <origin rpy="0 0 0" xyz="-2.3E-05 -0.010364 -0.07336"/>
      <mass value="1.3773"/>
      <inertia ixx="0.00457" ixy="1E-06" ixz="2E-06" iyy="0.004831" iyz="0.000448" izz="0.001409"/>
    </inertial>
    <visual>
      <origin rpy="0 0 0" xyz="0 0 0"/>
      <geometry>
        <mesh filename="eddie_meshes/shoulder_link.dae"/>
      </geometry>
      <material name="">
        <color rgba="0.75294 0.75294 0.75294 1"/>
      </material>
    </visual>
    <collision>
      <origin rpy="0 0 0" xyz="0 0 0"/>
      <geometry>
        <mesh filename="eddie_meshes/shoulder_link.dae"/>
      </geometry>
    </collision>
  </link>
  <joint name="eddie_right_arm_joint_1" type="continuous">
    <origin rpy="3.1416 2.7629E-18 -4.9305E-36" xyz="0 0 0.15643"/>
    <parent link="eddie_right_arm_base_link"/>
    <child link="eddie_right_arm_shoulder_link"/>
    <axis xyz="0 0 1"/>
    <limit effort="39" velocity="1.3963"/>
  </joint>
  <link name="eddie_right_arm_half_arm_1_link">
    <inertial>
      <origin rpy="0 0 0" xyz="-4.4E-05 -0.09958 -0.013278"/>
      <mass value="1.1636"/>
      <inertia ixx="0.011088" ixy="5E-06" ixz="0" iyy="0.001072" iyz="-0.000691" izz="0.011255"/>
    </inertial>
    <visual>
      <origin rpy="0 0 0" xyz="0 0 0"/>
      <geometry>
        <mesh filename="eddie_meshes/half_arm_1_link.dae"/>
      </geometry>
      <material name="">
        <color rgba="0.75294 0.75294 0.75294 1"/>
      </material>
    </visual>
    <collision>
      <origin rpy="0 0 0" xyz="0 0 0"/>
      <geometry>
        <mesh filename="eddie_meshes/half_arm_1_link.dae"/>
      </geometry>
    </collision>
  </link>
  <joint name="eddie_right_arm_joint_2" type="revolute">
    <origin rpy="1.5708 2.1343E-17 -1.1102E-16" xyz="0 0.005375 -0.12838"/>
    <parent link="eddie_right_arm_shoulder_link"/>
    <child link="eddie_right_arm_half_arm_1_link"/>
    <axis xyz="0 0 1"/>
    <limit effort="39" lower="-2.24" upper="2.24" velocity="1.3963"/>
  </joint>
  <link name="eddie_right_arm_half_arm_2_link">
    <inertial>
      <origin rpy="0 0 0" xyz="-4.4E-05 -0.006641 -0.117892"/>
      <mass value="1.1636"/>
      <inertia ixx="0.010932" ixy="0" ixz="-7E-06" iyy="0.011127" iyz="0.000606" izz="0.001043"/>
    </inertial>
    <visual>
      <origin rpy="0 0 0" xyz="0 0 0"/>
      <geometry>
        <mesh filename="eddie_meshes/half_arm_2_link.dae"/>
      </geometry>
      <material name="">
        <color rgba="0.75294 0.75294 0.75294 1"/>
      </material>
    </visual>
    <collision>
      <origin rpy="0 0 0" xyz="0 0 0"/>
      <geometry>
        <mesh filename="eddie_meshes/half_arm_2_link.dae"/>
      </geometry>
    </collision>
  </link>
  <joint name="eddie_right_arm_joint_3" type="continuous">
    <origin rpy="-1.5708 1.2326E-32 -2.9122E-16" xyz="0 -0.21038 -0.006375"/>
    <parent link="eddie_right_arm_half_arm_1_link"/>
    <child link="eddie_right_arm_half_arm_2_link"/>
    <axis xyz="0 0 1"/>
    <limit effort="39" velocity="1.3963"/>
  </joint>
  <link name="eddie_right_arm_forearm_link">
    <inertial>
      <origin rpy="0 0 0" xyz="-1.8E-05 -0.075478 -0.015006"/>
      <mass value="0.9302"/>
      <inertia ixx="0.008147" ixy="-1E-06" ixz="0" iyy="0.000631" iyz="-0.0005" izz="0.008316"/>
    </inertial>
    <visual>
      <origin rpy="0 0 0" xyz="0 0 0"/>
      <geometry>
        <mesh filename="eddie_meshes/forearm_link.dae"/>
      </geometry>
      <material name="">
        <color rgba="0.75294 0.75294 0.75294 1"/>
      </material>
    </visual>
    <collision>
      <origin rpy="0 0 0" xyz="0 0 0"/>
      <geometry>
        <mesh filename="eddie_meshes/forearm_link.dae"/>
      </geometry>
    </collision>
  </link>
  <joint name="eddie_right_arm_joint_4" type="revolute">
    <origin rpy="1.5708 -6.6954E-17 -1.6653E-16" xyz="0 0.006375 -0.21038"/>
    <parent link="eddie_right_arm_half_arm_2_link"/>
    <child link="eddie_right_arm_forearm_link"/>
    <axis xyz="0 0 1"/>
    <limit effort="39" lower="-2.57" upper="2.57" velocity="1.3963"/>
  </joint>
  <link name="eddie_right_arm_spherical_wrist_1_link">
    <inertial>
      <origin rpy="0 0 0" xyz="1E-06 -0.009432 -0.063883"/>
      <mass value="0.6781"/>
      <inertia ixx="0.001596" ixy="0" ixz="0" iyy="0.001607" iyz="0.000256" izz="0.000399"/>
    </inertial>
    <visual>
      <origin rpy="0 0 0" xyz="0 0 0"/>
      <geometry>
        <mesh filename="eddie_meshes/spherical_wrist_1_link.dae"/>
      </geometry>
      <material name="">
        <color rgba="0.75294 0.75294 0.75294 1"/>
      </material>
    </visual>
    <collision>
      <origin rpy="0 0 0" xyz="0 0 0"/>
      <geometry>
        <mesh filename="eddie_meshes/spherical_wrist_1_link.dae"/>
      </geometry>
    </collision>
  </link>
  <joint name="eddie_right_arm_joint_5" type="continuous">
    <origin rpy="-1.5708 2.2204E-16 -6.373E-17" xyz="0 -0.20843 -0.006375"/>
    <parent link="eddie_right_arm_forearm_link"/>
    <child link="eddie_right_arm_spherical_wrist_1_link"/>
    <axis xyz="0 0 1"/>
    <limit effort="9" velocity="1.2218"/>
  </joint>
  <link name="eddie_right_arm_spherical_wrist_2_link">
    <inertial>
      <origin rpy="0 0 0" xyz="1E-06 -0.045483 -0.00965"/>
      <mass value="0.6781"/>
      <inertia ixx="0.001641" ixy="0" ixz="0" iyy="0.00041" iyz="-0.000278" izz="0.001641"/>
    </inertial>
    <visual>
      <origin rpy="0 0 0" xyz="0 0 0"/>
      <geometry>
        <mesh filename="eddie_meshes/spherical_wrist_2_link.dae"/>
      </geometry>
      <material name="">
        <color rgba="0.75294 0.75294 0.75294 1"/>
      </material>
    </visual>
    <collision>
      <origin rpy="0 0 0" xyz="0 0 0"/>
      <geometry>
        <mesh filename="eddie_meshes/spherical_wrist_2_link.dae"/>
      </geometry>
    </collision>
  </link>
  <joint name="eddie_right_arm_joint_6" type="revolute">
    <origin rpy="1.5708 9.2076E-28 -8.2157E-15" xyz="0 0.00017505 -0.10593"/>
    <parent link="eddie_right_arm_spherical_wrist_1_link"/>
    <child link="eddie_right_arm_spherical_wrist_2_link"/>
    <axis xyz="0 0 1"/>
    <limit effort="9" lower="-2.09" upper="2.09" velocity="1.2218"/>
  </joint>
  <link name="eddie_right_arm_bracelet_link">
    <inertial>
      <origin rpy="0 0 0" xyz="0.000281 0.011402 -0.029798"/>
      <mass value="0.5"/>
      <inertia ixx="0.000587" ixy="3E-06" ixz="3E-06" iyy="0.000369" iyz="-0.000118" izz="0.000609"/>
    </inertial>
    <visual>
      <origin rpy="0 0 0" xyz="0 0 0"/>
      <geometry>
        <mesh filename="eddie_meshes/bracelet_with_vision_link.dae"/>
      </geometry>
      <material name="">
        <color rgba="0.75294 0.75294 0.75294 1"/>
      </material>
    </visual>
    <collision>
      <origin rpy="0 0 0" xyz="0 0 0"/>
      <geometry>
        <mesh filename="eddie_meshes/bracelet_with_vision_link.dae"/>
      </geometry>
    </collision>
  </link>
  <joint name="eddie_right_arm_joint_7" type="continuous">
    <origin rpy="-1.5708 -5.5511E-17 9.6396E-17" xyz="0 -0.10593 -0.00017505"/>
    <parent link="eddie_right_arm_spherical_wrist_2_link"/>
    <child link="eddie_right_arm_bracelet_link"/>
    <axis xyz="0 0 1"/>
    <limit effort="9" velocity="1.2218"/>
  </joint>
  <link name="eddie_right_arm_end_effector_link"/>
  <joint name="eddie_right_arm_end_effector" type="fixed">
    <origin rpy="3.14159265358979 1.09937075168372E-32 0" xyz="0 0 -0.0615250000000001"/>
    <parent link="eddie_right_arm_bracelet_link"/>
    <child link="eddie_right_arm_end_effector_link"/>
    <axis xyz="0 0 0"/>
  </joint>
  <link name="eddie_right_arm_camera_link"/>
  <joint name="eddie_right_arm_camera_module" type="fixed">
    <origin rpy="3.141592653589793 3.141592653589793 0" xyz="0 0.05639 -0.00305"/>
    <parent link="eddie_right_arm_end_effector_link"/>
    <child link="eddie_right_arm_camera_link"/>
  </joint>
  <link name="eddie_right_arm_camera_depth_frame"/>
  <joint name="eddie_right_arm_depth_module" type="fixed">
    <origin rpy="3.141592653589793 3.141592653589793 0" xyz="0.0275 0.066 -0.00305"/>
    <parent link="eddie_right_arm_end_effector_link"/>
    <child link="eddie_right_arm_camera_depth_frame"/>
  </joint>
  <link name="eddie_right_arm_camera_color_frame"/>
  <joint name="eddie_right_arm_color_module" type="fixed">
    <origin rpy="3.141592653589793 3.141592653589793 0" xyz="0 0.05639 -0.00305"/>
    <parent link="eddie_right_arm_end_effector_link"/>
    <child link="eddie_right_arm_camera_color_frame"/>
  </joint>
  <link name="eddie_right_arm_robotiq_85_base_link">
    <visual>
      <geometry>
        <mesh filename="eddie_meshes/visual/2f_85/robotiq_base.dae"/>
      </geometry>
    </visual>
    <collision>
      <geometry>
        <mesh filename="eddie_meshes/collision/2f_85/robotiq_base.stl"/>
      </geometry>
    </collision>
    <inertial>
      <origin rpy="0 0 0" xyz="0.0 2.274e-05 0.03232288"/>
      <mass value="6.6320197e-01"/>
      <inertia ixx="5.1617816e-04" ixy="2.936e-8" ixz="0.0" iyy="5.8802208e-04" iyz="-3.2296e-7" izz="3.9462776e-04"/>
    </inertial>
  </link>
  <link name="eddie_right_arm_robotiq_85_left_knuckle_link">
    <visual>
      <geometry>
        <mesh filename="eddie_meshes/visual/2f_85/left_knuckle.dae"/>
      </geometry>
    </visual>
    <collision>
      <geometry>
        <mesh filename="eddie_meshes/collision/2f_85/left_knuckle.stl"/>
      </geometry>
    </collision>
    <inertial>
      <origin rpy="0 0 0" xyz="0.01213197 0.0002 -0.00058647"/>
      <mass value="1.384773208e-02"/>
      <inertia ixx="3.5232e-7" ixy="0.0" ixz="1.1744e-7" iyy="2.31944e-6" iyz="0" izz="2.23136e-6"/>
    </inertial>
  </link>
  <link name="eddie_right_arm_robotiq_85_right_knuckle_link">
    <visual>
      <geometry>
        <mesh filename="eddie_meshes/visual/2f_85/right_knuckle.dae"/>
      </geometry>
    </visual>
    <collision>
      <geometry>
        <mesh filename="eddie_meshes/collision/2f_85/right_knuckle.stl"/>
      </geometry>
    </collision>
    <inertial>
      <origin rpy="0 0 0" xyz="-0.01213197 0.0002 -0.00058647"/>
      <mass value="1.384773208e-02"/>
      <inertia ixx="3.5232e-7" ixy="0.0" ixz="-1.1744e-7" iyy="2.31944e-6" iyz="0.0" izz="2.23136e-6"/>
    </inertial>
  </link>
  <link name="eddie_right_arm_robotiq_85_left_finger_link">
    <visual>
      <geometry>
        <mesh filename="eddie_meshes/visual/2f_85/left_finger.dae"/>
      </geometry>
    </visual>
    <collision>
      <geometry>
        <mesh filename="eddie_meshes/collision/2f_85/left_finger.stl"/>
      </geometry>
    </collision>
    <inertial>
      <origin rpy="0 0 0" xyz="0.00346899 -0.00079447 0.01867121"/>
      <mass value="4.260376752e-02"/>
      <inertia ixx="1.385792000000000e-05" ixy="0.0" ixz="-2.17264e-06" iyy="1.183208e-05" iyz="0.0" izz="5.19672e-06"/>
    </inertial>
  </link>
  <link name="eddie_right_arm_robotiq_85_right_finger_link">
    <visual>
      <geometry>
        <mesh filename="eddie_meshes/visual/2f_85/right_finger.dae"/>
      </geometry>
    </visual>
    <collision>
      <geometry>
        <mesh filename="eddie_meshes/collision/2f_85/right_finger.stl"/>
      </geometry>
    </collision>
    <inertial>
      <origin rpy="0 0 0" xyz="-0.00346899 -5.53e-06 0.01867121"/>
      <mass value="4.260376752000000e-02"/>
      <inertia ixx="1.385792e-05" ixy="0.0" ixz="2.17264e-06" iyy="1.183208e-05" iyz="0.0" izz="5.19672e-06"/>
    </inertial>
  </link>
  <link name="eddie_right_arm_robotiq_85_left_inner_knuckle_link">
    <visual>
      <geometry>
        <mesh filename="eddie_meshes/visual/2f_85/left_inner_knuckle.dae"/>
      </geometry>
    </visual>
    <collision>
      <geometry>
        <mesh filename="eddie_meshes/collision/2f_85/left_inner_knuckle.stl"/>
      </geometry>
    </collision>
    <inertial>
      <origin rpy="0 0 0" xyz="0.01897699 0.00015001 0.02247101"/>
      <mass value="2.969376448e-02"/>
      <inertia ixx="9.57136e-06" ixy="0.0" ixz="-3.93424e-06" iyy="8.69056e-06" iyz="0.0" izz="8.19144e-06"/>
    </inertial>
  </link>
  <link name="eddie_right_arm_robotiq_85_right_inner_knuckle_link">
    <visual>
      <geometry>
        <mesh filename="eddie_meshes/visual/2f_85/right_inner_knuckle.dae"/>
      </geometry>
    </visual>
    <collision>
      <geometry>
        <mesh filename="eddie_meshes/collision/2f_85/right_inner_knuckle.stl"/>
      </geometry>
    </collision>
    <inertial>
      <origin rpy="0 0 0" xyz="-0.01926824 5.001e-05 0.02222178"/>
      <mass value="2.969376448e-02"/>
      <inertia ixx="9.42456e-06" ixy="0.0" ixz="3.9636e-06" iyy="8.69056e-06" iyz="0.0" izz="8.33824e-06"/>
    </inertial>
  </link>
  <link name="eddie_right_arm_robotiq_85_left_finger_tip_link">
    <visual>
      <geometry>
        <mesh filename="eddie_meshes/visual/2f_85/left_finger_tip.dae"/>
      </geometry>
    </visual>
    <collision>
      <geometry>
        <mesh filename="eddie_meshes/collision/2f_85/left_finger_tip.stl"/>
      </geometry>
      <surface>
        <friction>
          <ode>
            <mu1>100000.0</mu1>
            <mu2>100000.0</mu2>
          </ode>
        </friction>
        <contact>
          <ode>
            <kp>1e+5</kp>
            <kd>1</kd>
            <soft_cfm>0</soft_cfm>
            <soft_erp>0.2</soft_erp>
            <minDepth>0.002</minDepth>
            <maxVel>0</maxVel>
          </ode>
        </contact>
      </surface>
    </collision>
    <inertial>
      <origin rpy="0 0 0" xyz="-0.01456706 -0.0008 0.01649701"/>
      <mass value="4.268588744e-02"/>
      <inertia ixx="1.048152e-05" ixy="0.0" ixz="3.5232e-6" iyy="1.197888e-05" iyz="0.0" izz="4.22784e-06"/>
    </inertial>
  </link>
  <link name="eddie_right_arm_robotiq_85_right_finger_tip_link">
    <visual>
      <geometry>
        <mesh filename="eddie_meshes/visual/2f_85/right_finger_tip.dae"/>
      </geometry>
    </visual>
    <collision>
      <geometry>
        <mesh filename="eddie_meshes/collision/2f_85/right_finger_tip.stl"/>
      </geometry>
      <surface>
        <friction>
          <ode>
            <mu1>100000.0</mu1>
            <mu2>100000.0</mu2>
          </ode>
        </friction>
        <contact>
          <ode>
            <kp>1e+5</kp>
            <kd>1</kd>
            <soft_cfm>0</soft_cfm>
            <soft_erp>0.2</soft_erp>
            <minDepth>0.002</minDepth>
            <maxVel>0</maxVel>
          </ode>
        </contact>
      </surface>
    </collision>
    <inertial>
      <origin rpy="0 0 0" xyz="0.01456706 5e-05 0.01649701"/>
      <mass value="4.268588744e-02"/>
      <inertia ixx="1.048152e-05" ixy="0.0" ixz="-3.5232e-06" iyy="1.197888e-05" iyz="0.0" izz="4.22784e-06"/>
    </inertial>
  </link>
  <joint name="eddie_right_arm_robotiq_85_base_joint" type="fixed">
    <parent link="eddie_right_arm_end_effector_link"/>
    <child link="eddie_right_arm_robotiq_85_base_link"/>
    <origin rpy="0 0 0" xyz="0 0 0"/>
  </joint>
  <joint name="eddie_right_arm_robotiq_85_left_knuckle_joint" type="revolute">
    <parent link="eddie_right_arm_robotiq_85_base_link"/>
    <child link="eddie_right_arm_robotiq_85_left_knuckle_link"/>
    <axis xyz="0 -1 0"/>
    <origin rpy="0 0 0" xyz="0.03060114 0.0 0.05490452"/>
    <limit effort="50" lower="0.0" upper="0.8" velocity="0.5"/>
  </joint>
  <joint name="eddie_right_arm_robotiq_85_right_knuckle_joint" type="revolute">
    <parent link="eddie_right_arm_robotiq_85_base_link"/>
    <child link="eddie_right_arm_robotiq_85_right_knuckle_link"/>
    <axis xyz="0 -1 0"/>
    <origin rpy="0 0 0" xyz="-0.03060114 0.0 0.05490452"/>
    <limit effort="50" lower="-0.8" upper="0.0" velocity="0.5"/>
    <mimic joint="eddie_right_arm_robotiq_85_left_knuckle_joint" multiplier="-1"/>
  </joint>
  <joint name="eddie_right_arm_robotiq_85_left_finger_joint" type="fixed">
    <parent link="eddie_right_arm_robotiq_85_left_knuckle_link"/>
    <child link="eddie_right_arm_robotiq_85_left_finger_link"/>
    <origin rpy="0 0 0" xyz="0.03152616 0.0 -0.00376347"/>
  </joint>
  <joint name="eddie_right_arm_robotiq_85_right_finger_joint" type="fixed">
    <parent link="eddie_right_arm_robotiq_85_right_knuckle_link"/>
    <child link="eddie_right_arm_robotiq_85_right_finger_link"/>
    <origin rpy="0 0 0" xyz="-0.03152616 0.0 -0.00376347"/>
  </joint>
  <joint name="eddie_right_arm_robotiq_85_left_inner_knuckle_joint" type="continuous">
    <parent link="eddie_right_arm_robotiq_85_base_link"/>
    <child link="eddie_right_arm_robotiq_85_left_inner_knuckle_link"/>
    <axis xyz="0 -1 0"/>
    <origin rpy="0 0 0" xyz="0.0127 0.0 0.06142"/>
    <mimic joint="eddie_right_arm_robotiq_85_left_knuckle_joint"/>
  </joint>
  <joint name="eddie_right_arm_robotiq_85_right_inner_knuckle_joint" type="continuous">
    <parent link="eddie_right_arm_robotiq_85_base_link"/>
    <child link="eddie_right_arm_robotiq_85_right_inner_knuckle_link"/>
    <axis xyz="0 -1 0"/>
    <origin rpy="0 0 0" xyz="-0.0127 0.0 0.06142"/>
    <mimic joint="eddie_right_arm_robotiq_85_left_knuckle_joint" multiplier="-1"/>
  </joint>
  <joint name="eddie_right_arm_robotiq_85_left_finger_tip_joint" type="continuous">
    <parent link="eddie_right_arm_robotiq_85_left_finger_link"/>
    <child link="eddie_right_arm_robotiq_85_left_finger_tip_link"/>
    <axis xyz="0 -1 0"/>
    <origin rpy="0 0 0" xyz="0.00563134 0.0 0.04718515"/>
    <mimic joint="eddie_right_arm_robotiq_85_left_knuckle_joint" multiplier="-1"/>
  </joint>
  <joint name="eddie_right_arm_robotiq_85_right_finger_tip_joint" type="continuous">
    <parent link="eddie_right_arm_robotiq_85_right_finger_link"/>
    <child link="eddie_right_arm_robotiq_85_right_finger_tip_link"/>
    <axis xyz="0 -1 0"/>
    <origin rpy="0 0 0" xyz="-0.00563134 0.0 0.04718515"/>
    <mimic joint="eddie_right_arm_robotiq_85_left_knuckle_joint"/>
  </joint>
</robot>
